Workbook

Sheet Indice
S1: {id:97,title: "He aquí que nuestro espejo es el Señor", subtitle: "Oda XIII de Salomó", category: "Catecumenado", moments: ["Cuaresma", "Pascua", "Laudes/Visperas"], url: "/cantos/src/chtml/h/heaquiquenuestroespejoeselsenor.html"},
A2: # | B2: Or# | C2: Canto | D2: subtitle | E2: iniciar | F2: Categoria | G2: Adviento | H2: Navidad | I2: Cuaresma | J2: Pascua | K2: Pentecostés | L2: Entrada | M2: Virgen | N2: Paz | O2: Pan | P2: Comunión | Q2: Niños | R2: Laudes | S2: Nuevo Testamento | T2: Antiguo Testamento | U2: Final | V2: URL | W2: Codigo | AM2: x
A3: 237 | B3: 1 | C3: A la cena del Cordero | D3: Himno lat. «Ad cenam Agni providi» | E3: =LOWER(LEFT(Table1[[#This Row],[Canto]],1)) -> a | F3: Eleccion | G3: =IFERROR(IF(VLOOKUP(C3,Adviento!A:C,3,FALSE)=Table1[[#Headers],[Adviento]],Table1[[#Headers],[Adviento]],""),"") | H3: =IFERROR(IF(VLOOKUP(C3,Navidad!A:C,3,FALSE)=Table1[[#Headers],[Navidad]],Table1[[#Headers],[Navidad]],""),"") | I3: =IFERROR(IF(VLOOKUP(C3,Cuaresma!A:C,3,FALSE)=Table1[[#Headers],[Cuaresma]],Table1[[#Headers],[Cuaresma]],""),"") | J3: =IFERROR(IF(VLOOKUP(C3,Pascua!A:C,3,FALSE)=Table1[[#Headers],[Pascua]],Table1[[#Headers],[Pascua]],""),"") -> Pascua | K3: =IFERROR(IF(VLOOKUP(C3,Pentecostés!A:C,3,FALSE)=Table1[[#Headers],[Pentecostés]],Table1[[#Headers],[Pentecostés]],""),"") -> Pentecostés | L3: =IFERROR(IF(VLOOKUP(C3,Entrada!A:C,3,FALSE)=Table1[[#Headers],[Entrada]],Table1[[#Headers],[Entrada]],""),"") | M3: =IFERROR(IF(VLOOKUP(C3,Virgen!A:C,3,FALSE)=Table1[[#Headers],[Virgen]],Table1[[#Headers],[Virgen]],""),"") | N3: =IFERROR(IF(VLOOKUP(C3,Paz!A:C,3,FALSE)=Table1[[#Headers],[Paz]],Table1[[#Headers],[Paz]],""),"") | O3: =IFERROR(IF(VLOOKUP(C3,Pan!A:C,3,FALSE)=Table1[[#Headers],[Pan]],Table1[[#Headers],[Pan]],""),"") | P3: =IFERROR(IF(VLOOKUP(C3,Comunión!A:C,3,FALSE)=Table1[[#Headers],[Comunión]],Table1[[#Headers],[Comunión]],""),"") | Q3: =IFERROR(IF(VLOOKUP(C3,Niños!A:C,3,FALSE)=Table1[[#Headers],[Niños]],Table1[[#Headers],[Niños]],""),"") | R3: =IFERROR(IF(VLOOKUP(C3,Laudes!A:C,3,FALSE)=Table1[[#Headers],[Laudes]],Table1[[#Headers],[Laudes]],""),"") -> Laudes | S3: =IFERROR(IF(VLOOKUP(C3,'Nuevo Testamento'!A:C,3,FALSE)=Table1[[#Headers],[Nuevo Testamento]],Table1[[#Headers],[Nuevo Testamento]],""),"") | T3: =IFERROR(IF(VLOOKUP(C3,'Antiguo Testamento'!A:C,3,FALSE)=Table1[[#Headers],[Antiguo Testamento]],Table1[[#Headers],[Antiguo Testamento]],""),"") | U3: =IFERROR(IF(VLOOKUP(C3,Final!A:C,3,FALSE)=Table1[[#Headers],[Final]],Table1[[#Headers],[Final]],""),"") | V3: {=_xlfn.LET( _xlpm.texto_limpio, _xlfn.REDUCE( LOWER(Table1[[#This Row],[Canto]]), {"á";"é";"í";"ó";"ú";"ñ";",";" "}, _xlfn.LAMBDA(_xlpm.acum,_xlpm.caracter, SUBSTITUTE(_xlpm.acum, _xlpm.caracter, CHOOSE(MATCH(_xlpm.caracter, {"á";"é";"í";"ó";"ú";"ñ";",";" "}, 0), "a","e","i","o","u","n","",""))) ), _xlfn.CONCAT("/cantos/src/chtml/", Table1[[#This Row],[iniciar]], "/", _xlpm.texto_limpio, ".html") )} -> /cantos/src/chtml/a/alacenadelcordero.html | W3: =_xlfn.CONCAT("{id:",Table1[[#This Row],[Or'#]],",","title: ","""",Table1[[#This Row],[Canto]],"""",", subtitle: ","""",Table1[[#This Row],[subtitle]],"""",", ","category: ","""",Table1[[#This Row],[Categoria]],"""",", moments: [","""",Table1[[#This Row],[Adviento]],""",","""",Table1[[#This Row],[Navidad]],""",","""",Table1[[#This Row],[Cuaresma]],""",","""",Table1[[#This Row],[Pascua]],""",","""",Table1[[#This Row],[Pentecostés]],""",","""",Table1[[#This Row],[Entrada]],""",","""",Table1[[#This Row],[Virgen]],""",","""",Table1[[#This Row],[Paz]],""",","""",Table1[[#This Row],[Pan]],""",","""",Table1[[#This Row],[Comunión]],""",","""",Table1[[#This Row],[Niños]],""",","""",Table1[[#This Row],[Laudes]],""",","""",Table1[[#This Row],[Nuevo Testamento]],""",","""",Table1[[#This Row],[Antiguo Testamento]],""",","""",Table1[[#This Row],[Final]],"""","], url: ","""",Table1[[#This Row],[URL]],"""","},") -> {id:1,title: "A la cena del Cordero", subtitle: "Himno lat. «Ad cenam Agni providi»", category: "Eleccion", moments: ["","","","Pascua","Pentecostés","","","","","","","Laudes","","",""], url: "/cantos/src/chtml/a/alacenadelcordero.html"},
A4: 1 | B4: 2 | C4: A la víctima pascual | D4: Secuencia de Pascua - Himno lat. «Victimae paschall laudes» | E4: =LOWER(LEFT(Table1[[#This Row],[Canto]],1)) -> a | F4: Precatecumenado | G4: =IFERROR(IF(VLOOKUP(C4,Adviento!A:C,3,FALSE)=Table1[[#Headers],[Adviento]],Table1[[#Headers],[Adviento]],""),"") | H4: =IFERROR(IF(VLOOKUP(C4,Navidad!A:C,3,FALSE)=Table1[[#Headers],[Navidad]],Table1[[#Headers],[Navidad]],""),"") | I4: =IFERROR(IF(VLOOKUP(C4,Cuaresma!A:C,3,FALSE)=Table1[[#Headers],[Cuaresma]],Table1[[#Headers],[Cuaresma]],""),"") | J4: =IFERROR(IF(VLOOKUP(C4,Pascua!A:C,3,FALSE)=Table1[[#Headers],[Pascua]],Table1[[#Headers],[Pascua]],""),"") -> Pascua | K4: =IFERROR(IF(VLOOKUP(C4,Pentecostés!A:C,3,FALSE)=Table1[[#Headers],[Pentecostés]],Table1[[#Headers],[Pentecostés]],""),"") -> Pentecostés | L4: =IFERROR(IF(VLOOKUP(C4,Entrada!A:C,3,FALSE)=Table1[[#Headers],[Entrada]],Table1[[#Headers],[Entrada]],""),"") | M4: =IFERROR(IF(VLOOKUP(C4,Virgen!A:C,3,FALSE)=Table1[[#Headers],[Virgen]],Table1[[#Headers],[Virgen]],""),"") | N4: =IFERROR(IF(VLOOKUP(C4,Paz!A:C,3,FALSE)=Table1[[#Headers],[Paz]],Table1[[#Headers],[Paz]],""),"") | O4: =IFERROR(IF(VLOOKUP(C4,Pan!A:C,3,FALSE)=Table1[[#Headers],[Pan]],Table1[[#Headers],[Pan]],""),"") | P4: =IFERROR(IF(VLOOKUP(C4,Comunión!A:C,3,FALSE)=Table1[[#Headers],[Comunión]],Table1[[#Headers],[Comunión]],""),"") | Q4: =IFERROR(IF(VLOOKUP(C4,Niños!A:C,3,FALSE)=Table1[[#Headers],[Niños]],Table1[[#Headers],[Niños]],""),"") | R4: =IFERROR(IF(VLOOKUP(C4,Laudes!A:C,3,FALSE)=Table1[[#Headers],[Laudes]],Table1[[#Headers],[Laudes]],""),"") | S4: =IFERROR(IF(VLOOKUP(C4,'Nuevo Testamento'!A:C,3,FALSE)=Table1[[#Headers],[Nuevo Testamento]],Table1[[#Headers],[Nuevo Testamento]],""),"") -> Nuevo Testamento | T4: =IFERROR(IF(VLOOKUP(C4,'Antiguo Testamento'!A:C,3,FALSE)=Table1[[#Headers],[Antiguo Testamento]],Table1[[#Headers],[Antiguo Testamento]],""),"") | U4: =IFERROR(IF(VLOOKUP(C4,Final!A:C,3,FALSE)=Table1[[#Headers],[Final]],Table1[[#Headers],[Final]],""),"") | V4: {=_xlfn.LET( _xlpm.texto_limpio, _xlfn.REDUCE( LOWER(Table1[[#This Row],[Canto]]), {"á";"é";"í";"ó";"ú";"ñ";",";" "}, _xlfn.LAMBDA(_xlpm.acum,_xlpm.caracter, SUBSTITUTE(_xlpm.acum, _xlpm.caracter, CHOOSE(MATCH(_xlpm.caracter, {"á";"é";"í";"ó";"ú";"ñ";",";" "}, 0), "a","e","i","o","u","n","",""))) ), _xlfn.CONCAT("/cantos/src/chtml/", Table1[[#This Row],[iniciar]], "/", _xlpm.texto_limpio, ".html") )} -> /cantos/src/chtml/a/alavictimapascual.html | W4: =_xlfn.CONCAT("{id:",Table1[[#This Row],[Or'#]],",","title: ","""",Table1[[#This Row],[Canto]],"""",", subtitle: ","""",Table1[[#This Row],[subtitle]],"""",", ","category: ","""",Table1[[#This Row],[Categoria]],"""",", moments: [","""",Table1[[#This Row],[Adviento]],""",","""",Table1[[#This Row],[Navidad]],""",","""",Table1[[#This Row],[Cuaresma]],""",","""",Table1[[#This Row],[Pascua]],""",","""",Table1[[#This Row],[Pentecostés]],""",","""",Table1[[#This Row],[Entrada]],""",","""",Table1[[#This Row],[Virgen]],""",","""",Table1[[#This Row],[Paz]],""",","""",Table1[[#This Row],[Pan]],""",","""",Table1[[#This Row],[Comunión]],""",","""",Table1[[#This Row],[Niños]],""",","""",Table1[[#This Row],[Laudes]],""",","""",Table1[[#This Row],[Nuevo Testamento]],""",","""",Table1[[#This Row],[Antiguo Testamento]],""",","""",Table1[[#This Row],[Final]],"""","], url: ","""",Table1[[#This Row],[URL]],"""","},") -> {id:2,title: "A la víctima pascual", subtitle: "Secuencia de Pascua - Himno lat. «Victimae paschall laudes» ", category: "Precatecumenado", moments: ["","","","Pascua","Pentecostés","","","","","","","","Nuevo Testamento","",""], url: "/cantos/src/chtml/a/alavictimapascual.html"},
A5: 2 | B5: 3 | C5: A nadie demos ocasión de tropiezo | D5: 2ª Corintios 6,3ss | E5: =LOWER(LEFT(Table1[[#This Row],[Canto]],1)) -> a | F5: Precatecumenado | G5: =IFERROR(IF(VLOOKUP(C5,Adviento!A:C,3,FALSE)=Table1[[#Headers],[Adviento]],Table1[[#Headers],[Adviento]],""),"") | H5: =IFERROR(IF(VLOOKUP(C5,Navidad!A:C,3,FALSE)=Table1[[#Headers],[Navidad]],Table1[[#Headers],[Navidad]],""),"") | I5: =IFERROR(IF(VLOOKUP(C5,Cuaresma!A:C,3,FALSE)=Table1[[#Headers],[Cuaresma]],Table1[[#Headers],[Cuaresma]],""),"") | J5: =IFERROR(IF(VLOOKUP(C5,Pascua!A:C,3,FALSE)=Table1[[#Headers],[Pascua]],Table1[[#Headers],[Pascua]],""),"") | K5: =IFERROR(IF(VLOOKUP(C5,Pentecostés!A:C,3,FALSE)=Table1[[#Headers],[Pentecostés]],Table1[[#Headers],[Pentecostés]],""),"") | L5: =IFERROR(IF(VLOOKUP(C5,Entrada!A:C,3,FALSE)=Table1[[#Headers],[Entrada]],Table1[[#Headers],[Entrada]],""),"") | M5: =IFERROR(IF(VLOOKUP(C5,Virgen!A:C,3,FALSE)=Table1[[#Headers],[Virgen]],Table1[[#Headers],[Virgen]],""),"") | N5: =IFERROR(IF(VLOOKUP(C5,Paz!A:C,3,FALSE)=Table1[[#Headers],[Paz]],Table1[[#Headers],[Paz]],""),"") | O5: =IFERROR(IF(VLOOKUP(C5,Pan!A:C,3,FALSE)=Table1[[#Headers],[Pan]],Table1[[#Headers],[Pan]],""),"") | P5: =IFERROR(IF(VLOOKUP(C5,Comunión!A:C,3,FALSE)=Table1[[#Headers],[Comunión]],Table1[[#Headers],[Comunión]],""),"") | Q5: =IFERROR(IF(VLOOKUP(C5,Niños!A:C,3,FALSE)=Table1[[#Headers],[Niños]],Table1[[#Headers],[Niños]],""),"") | R5: =IFERROR(IF(VLOOKUP(C5,Laudes!A:C,3,FALSE)=Table1[[#Headers],[Laudes]],Table1[[#Headers],[Laudes]],""),"") | S5: =IFERROR(IF(VLOOKUP(C5,'Nuevo Testamento'!A:C,3,FALSE)=Table1[[#Headers],[Nuevo Testamento]],Table1[[#Headers],[Nuevo Testamento]],""),"") -> Nuevo Testamento | T5: =IFERROR(IF(VLOOKUP(C5,'Antiguo Testamento'!A:C,3,FALSE)=Table1[[#Headers],[Antiguo Testamento]],Table1[[#Headers],[Antiguo Testamento]],""),"") | U5: =IFERROR(IF(VLOOKUP(C5,Final!A:C,3,FALSE)=Table1[[#Headers],[Final]],Table1[[#Headers],[Final]],""),"") | V5: {=_xlfn.LET( _xlpm.texto_limpio, _xlfn.REDUCE( LOWER(Table1[[#This Row],[Canto]]), {"á";"é";"í";"ó";"ú";"ñ";",";" "}, _xlfn.LAMBDA(_xlpm.acum,_xlpm.caracter, SUBSTITUTE(_xlpm.acum, _xlpm.caracter, CHOOSE(MATCH(_xlpm.caracter, {"á";"é";"í";"ó";"ú";"ñ";",";" "}, 0), "a","e","i","o","u","n","",""))) ), _xlfn.CONCAT("/cantos/src/chtml/", Table1[[#This Row],[iniciar]], "/", _xlpm.texto_limpio, ".html") )} -> /cantos/src/chtml/a/anadiedemosocasiondetropiezo.html | W5: =_xlfn.CONCAT("{id:",Table1[[#This Row],[Or'#]],",","title: ","""",Table1[[#This Row],[Canto]],"""",", subtitle: ","""",Table1[[#This Row],[subtitle]],"""",", ","category: ","""",Table1[[#This Row],[Categoria]],"""",", moments: [","""",Table1[[#This Row],[Adviento]],""",","""",Table1[[#This Row],[Navidad]],""",","""",Table1[[#This Row],[Cuaresma]],""",","""",Table1[[#This Row],[Pascua]],""",","""",Table1[[#This Row],[Pentecostés]],""",","""",Table1[[#This Row],[Entrada]],""",","""",Table1[[#This Row],[Virgen]],""",","""",Table1[[#This Row],[Paz]],""",","""",Table1[[#This Row],[Pan]],""",","""",Table1[[#This Row],[Comunión]],""",","""",Table1[[#This Row],[Niños]],""",","""",Table1[[#This Row],[Laudes]],""",","""",Table1[[#This Row],[Nuevo Testamento]],""",","""",Table1[[#This Row],[Antiguo Testamento]],""",","""",Table1[[#This Row],[Final]],"""","], url: ","""",Table1[[#This Row],[URL]],"""","},") -> {id:3,title: "A nadie demos ocasión de tropiezo", subtitle: "2ª Corintios 6,3ss", category: "Precatecumenado", moments: ["","","","","","","","","","","","","Nuevo Testamento","",""], url: "/cantos/src/chtml/a/anadiedemosocasiondetropiezo.html"},
A6: 3 | B6: 4 | C6: A ti levanto mis ojos | D6: Salmo 123 (122) | E6: =LOWER(LEFT(Table1[[#This Row],[Canto]],1)) -> a | F6: Precatecumenado | G6: =IFERROR(IF(VLOOKUP(C6,Adviento!A:C,3,FALSE)=Table1[[#Headers],[Adviento]],Table1[[#Headers],[Adviento]],""),"") | H6: =IFERROR(IF(VLOOKUP(C6,Navidad!A:C,3,FALSE)=Table1[[#Headers],[Navidad]],Table1[[#Headers],[Navidad]],""),"") | I6: =IFERROR(IF(VLOOKUP(C6,Cuaresma!A:C,3,FALSE)=Table1[[#Headers],[Cuaresma]],Table1[[#Headers],[Cuaresma]],""),"") -> Cuaresma | J6: =IFERROR(IF(VLOOKUP(C6,Pascua!A:C,3,FALSE)=Table1[[#Headers],[Pascua]],Table1[[#Headers],[Pascua]],""),"") | K6: =IFERROR(IF(VLOOKUP(C6,Pentecostés!A:C,3,FALSE)=Table1[[#Headers],[Pentecostés]],Table1[[#Headers],[Pentecostés]],""),"") | L6: =IFERROR(IF(VLOOKUP(C6,Entrada!A:C,3,FALSE)=Table1[[#Headers],[Entrada]],Table1[[#Headers],[Entrada]],""),"") | M6: =IFERROR(IF(VLOOKUP(C6,Virgen!A:C,3,FALSE)=Table1[[#Headers],[Virgen]],Table1[[#Headers],[Virgen]],""),"") | N6: =IFERROR(IF(VLOOKUP(C6,Paz!A:C,3,FALSE)=Table1[[#Headers],[Paz]],Table1[[#Headers],[Paz]],""),"") | O6: =IFERROR(IF(VLOOKUP(C6,Pan!A:C,3,FALSE)=Table1[[#Headers],[Pan]],Table1[[#Headers],[Pan]],""),"") | P6: =IFERROR(IF(VLOOKUP(C6,Comunión!A:C,3,FALSE)=Table1[[#Headers],[Comunión]],Table1[[#Headers],[Comunión]],""),"") | Q6: =IFERROR(IF(VLOOKUP(C6,Niños!A:C,3,FALSE)=Table1[[#Headers],[Niños]],Table1[[#Headers],[Niños]],""),"") | R6: =IFERROR(IF(VLOOKUP(C6,Laudes!A:C,3,FALSE)=Table1[[#Headers],[Laudes]],Table1[[#Headers],[Laudes]],""),"") | S6: =IFERROR(IF(VLOOKUP(C6,'Nuevo Testamento'!A:C,3,FALSE)=Table1[[#Headers],[Nuevo Testamento]],Table1[[#Headers],[Nuevo Testamento]],""),"") | T6: =IFERROR(IF(VLOOKUP(C6,'Antiguo Testamento'!A:C,3,FALSE)=Table1[[#Headers],[Antiguo Testamento]],Table1[[#Headers],[Antiguo Testamento]],""),"") -> Antiguo Testamento | U6: =IFERROR(IF(VLOOKUP(C6,Final!A:C,3,FALSE)=Table1[[#Headers],[Final]],Table1[[#Headers],[Final]],""),"") | V6: {=_xlfn.LET( _xlpm.texto_limpio, _xlfn.REDUCE( LOWER(Table1[[#This Row],[Canto]]), {"á";"é";"í";"ó";"ú";"ñ";",";" "}, _xlfn.LAMBDA(_xlpm.acum,_xlpm.caracter, SUBSTITUTE(_xlpm.acum, _xlpm.caracter, CHOOSE(MATCH(_xlpm.caracter, {"á";"é";"í";"ó";"ú";"ñ";",";" "}, 0), "a","e","i","o","u","n","",""))) ), _xlfn.CONCAT("/cantos/src/chtml/", Table1[[#This Row],[iniciar]], "/", _xlpm.texto_limpio, ".html") )} -> /cantos/src/chtml/a/atilevantomisojos.html | W6: =_xlfn.CONCAT("{id:",Table1[[#This Row],[Or'#]],",","title: ","""",Table1[[#This Row],[Canto]],"""",", subtitle: ","""",Table1[[#This Row],[subtitle]],"""",", ","category: ","""",Table1[[#This Row],[Categoria]],"""",", moments: [","""",Table1[[#This Row],[Adviento]],""",","""",Table1[[#This Row],[Navidad]],""",","""",Table1[[#This Row],[Cuaresma]],""",","""",Table1[[#This Row],[Pascua]],""",","""",Table1[[#This Row],[Pentecostés]],""",","""",Table1[[#This Row],[Entrada]],""",","""",Table1[[#This Row],[Virgen]],""",","""",Table1[[#This Row],[Paz]],""",","""",Table1[[#This Row],[Pan]],""",","""",Table1[[#This Row],[Comunión]],""",","""",Table1[[#This Row],[Niños]],""",","""",Table1[[#This Row],[Laudes]],""",","""",Table1[[#This Row],[Nuevo Testamento]],""",","""",Table1[[#This Row],[Antiguo Testamento]],""",","""",Table1[[#This Row],[Final]],"""","], url: ","""",Table1[[#This Row],[URL]],"""","},") -> {id:4,title: "A ti levanto mis ojos", subtitle: "Salmo 123 (122)", category: "Precatecumenado", moments: ["","","Cuaresma","","","","","","","","","","","Antiguo Testamento",""], url: "/cantos/src/chtml/a/atilevantomisojos.html"},
A7: 4 | B7: 5 | C7: A ti, Señor, en mi clamor imploro | D7: Salmo 142 (141) | E7: =LOWER(LEFT(Table1[[#This Row],[Canto]],1)) -> a | F7: Precatecumenado | G7: =IFERROR(IF(VLOOKUP(C7,Adviento!A:C,3,FALSE)=Table1[[#Headers],[Adviento]],Table1[[#Headers],[Adviento]],""),"") | H7: =IFERROR(IF(VLOOKUP(C7,Navidad!A:C,3,FALSE)=Table1[[#Headers],[Navidad]],Table1[[#Headers],[Navidad]],""),"") | I7: =IFERROR(IF(VLOOKUP(C7,Cuaresma!A:C,3,FALSE)=Table1[[#Headers],[Cuaresma]],Table1[[#Headers],[Cuaresma]],""),"") -> Cuaresma | J7: =IFERROR(IF(VLOOKUP(C7,Pascua!A:C,3,FALSE)=Table1[[#Headers],[Pascua]],Table1[[#Headers],[Pascua]],""),"") | K7: =IFERROR(IF(VLOOKUP(C7,Pentecostés!A:C,3,FALSE)=Table1[[#Headers],[Pentecostés]],Table1[[#Headers],[Pentecostés]],""),"") | L7: =IFERROR(IF(VLOOKUP(C7,Entrada!A:C,3,FALSE)=Table1[[#Headers],[Entrada]],Table1[[#Headers],[Entrada]],""),"") | M7: =IFERROR(IF(VLOOKUP(C7,Virgen!A:C,3,FALSE)=Table1[[#Headers],[Virgen]],Table1[[#Headers],[Virgen]],""),"") | N7: =IFERROR(IF(VLOOKUP(C7,Paz!A:C,3,FALSE)=Table1[[#Headers],[Paz]],Table1[[#Headers],[Paz]],""),"") | O7: =IFERROR(IF(VLOOKUP(C7,Pan!A:C,3,FALSE)=Table1[[#Headers],[Pan]],Table1[[#Headers],[Pan]],""),"") | P7: =IFERROR(IF(VLOOKUP(C7,Comunión!A:C,3,FALSE)=Table1[[#Headers],[Comunión]],Table1[[#Headers],[Comunión]],""),"") | Q7: =IFERROR(IF(VLOOKUP(C7,Niños!A:C,3,FALSE)=Table1[[#Headers],[Niños]],Table1[[#Headers],[Niños]],""),"") | R7: =IFERROR(IF(VLOOKUP(C7,Laudes!A:C,3,FALSE)=Table1[[#Headers],[Laudes]],Table1[[#Headers],[Laudes]],""),"") | S7: =IFERROR(IF(VLOOKUP(C7,'Nuevo Testamento'!A:C,3,FALSE)=Table1[[#Headers],[Nuevo Testamento]],Table1[[#Headers],[Nuevo Testamento]],""),"") | T7: =IFERROR(IF(VLOOKUP(C7,'Antiguo Testamento'!A:C,3,FALSE)=Table1[[#Headers],[Antiguo Testamento]],Table1[[#Headers],[Antiguo Testamento]],""),"") -> Antiguo Testamento | U7: =IFERROR(IF(VLOOKUP(C7,Final!A:C,3,FALSE)=Table1[[#Headers],[Final]],Table1[[#Headers],[Final]],""),"") | V7: {=_xlfn.LET( _xlpm.texto_limpio, _xlfn.REDUCE( LOWER(Table1[[#This Row],[Canto]]), {"á";"é";"í";"ó";"ú";"ñ";",";" "}, _xlfn.LAMBDA(_xlpm.acum,_xlpm.caracter, SUBSTITUTE(_xlpm.acum, _xlpm.caracter, CHOOSE(MATCH(_xlpm.caracter, {"á";"é";"í";"ó";"ú";"ñ";",";" "}, 0), "a","e","i","o","u","n","",""))) ), _xlfn.CONCAT("/cantos/src/chtml/", Table1[[#This Row],[iniciar]], "/", _xlpm.texto_limpio, ".html") )} -> /cantos/src/chtml/a/atisenorenmiclamorimploro.html | W7: =_xlfn.CONCAT("{id:",Table1[[#This Row],[Or'#]],",","title: ","""",Table1[[#This Row],[Canto]],"""",", subtitle: ","""",Table1[[#This Row],[subtitle]],"""",", ","category: ","""",Table1[[#This Row],[Categoria]],"""",", moments: [","""",Table1[[#This Row],[Adviento]],""",","""",Table1[[#This Row],[Navidad]],""",","""",Table1[[#This Row],[Cuaresma]],""",","""",Table1[[#This Row],[Pascua]],""",","""",Table1[[#This Row],[Pentecostés]],""",","""",Table1[[#This Row],[Entrada]],""",","""",Table1[[#This Row],[Virgen]],""",","""",Table1[[#This Row],[Paz]],""",","""",Table1[[#This Row],[Pan]],""",","""",Table1[[#This Row],[Comunión]],""",","""",Table1[[#This Row],[Niños]],""",","""",Table1[[#This Row],[Laudes]],""",","""",Table1[[#This Row],[Nuevo Testamento]],""",","""",Table1[[#This Row],[Antiguo Testamento]],""",","""",Table1[[#This Row],[Final]],"""","], url: ","""",Table1[[#This Row],[URL]],"""","},") -> {id:5,title: "A ti, Señor, en mi clamor imploro", subtitle: "Salmo 142 (141)", category: "Precatecumenado", moments: ["","","Cuaresma","","","","","","","","","","","Antiguo Testamento",""], url: "/cantos/src/chtml/a/atisenorenmiclamorimploro.html"},
A8: 5 | B8: 6 | C8: A ti, Señor, levanto mi alma | D8: Salmo 25 (24) | E8: =LOWER(LEFT(Table1[[#This Row],[Canto]],1)) -> a | F8: Precatecumenado | G8: =IFERROR(IF(VLOOKUP(C8,Adviento!A:C,3,FALSE)=Table1[[#Headers],[Adviento]],Table1[[#Headers],[Adviento]],""),"") | H8: =IFERROR(IF(VLOOKUP(C8,Navidad!A:C,3,FALSE)=Table1[[#Headers],[Navidad]],Table1[[#Headers],[Navidad]],""),"") | I8: =IFERROR(IF(VLOOKUP(C8,Cuaresma!A:C,3,FALSE)=Table1[[#Headers],[Cuaresma]],Table1[[#Headers],[Cuaresma]],""),"") -> Cuaresma | J8: =IFERROR(IF(VLOOKUP(C8,Pascua!A:C,3,FALSE)=Table1[[#Headers],[Pascua]],Table1[[#Headers],[Pascua]],""),"") | K8: =IFERROR(IF(VLOOKUP(C8,Pentecostés!A:C,3,FALSE)=Table1[[#Headers],[Pentecostés]],Table1[[#Headers],[Pentecostés]],""),"") | L8: =IFERROR(IF(VLOOKUP(C8,Entrada!A:C,3,FALSE)=Table1[[#Headers],[Entrada]],Table1[[#Headers],[Entrada]],""),"") | M8: =IFERROR(IF(VLOOKUP(C8,Virgen!A:C,3,FALSE)=Table1[[#Headers],[Virgen]],Table1[[#Headers],[Virgen]],""),"") | N8: =IFERROR(IF(VLOOKUP(C8,Paz!A:C,3,FALSE)=Table1[[#Headers],[Paz]],Table1[[#Headers],[Paz]],""),"") | O8: =IFERROR(IF(VLOOKUP(C8,Pan!A:C,3,FALSE)=Table1[[#Headers],[Pan]],Table1[[#Headers],[Pan]],""),"") | P8: =IFERROR(IF(VLOOKUP(C8,Comunión!A:C,3,FALSE)=Table1[[#Headers],[Comunión]],Table1[[#Headers],[Comunión]],""),"") | Q8: =IFERROR(IF(VLOOKUP(C8,Niños!A:C,3,FALSE)=Table1[[#Headers],[Niños]],Table1[[#Headers],[Niños]],""),"") | R8: =IFERROR(IF(VLOOKUP(C8,Laudes!A:C,3,FALSE)=Table1[[#Headers],[Laudes]],Table1[[#Headers],[Laudes]],""),"") | S8: =IFERROR(IF(VLOOKUP(C8,'Nuevo Testamento'!A:C,3,FALSE)=Table1[[#Headers],[Nuevo Testamento]],Table1[[#Headers],[Nuevo Testamento]],""),"") | T8: =IFERROR(IF(VLOOKUP(C8,'Antiguo Testamento'!A:C,3,FALSE)=Table1[[#Headers],[Antiguo Testamento]],Table1[[#Headers],[Antiguo Testamento]],""),"") -> Antiguo Testamento | U8: =IFERROR(IF(VLOOKUP(C8,Final!A:C,3,FALSE)=Table1[[#Headers],[Final]],Table1[[#Headers],[Final]],""),"") | V8: {=_xlfn.LET( _xlpm.texto_limpio, _xlfn.REDUCE( LOWER(Table1[[#This Row],[Canto]]), {"á";"é";"í";"ó";"ú";"ñ";",";" "}, _xlfn.LAMBDA(_xlpm.acum,_xlpm.caracter, SUBSTITUTE(_xlpm.acum, _xlpm.caracter, CHOOSE(MATCH(_xlpm.caracter, {"á";"é";"í";"ó";"ú";"ñ";",";" "}, 0), "a","e","i","o","u","n","",""))) ), _xlfn.CONCAT("/cantos/src/chtml/", Table1[[#This Row],[iniciar]], "/", _xlpm.texto_limpio, ".html") )} -> /cantos/src/chtml/a/atisenorlevantomialma.html | W8: =_xlfn.CONCAT("{id:",Table1[[#This Row],[Or'#]],",","title: ","""",Table1[[#This Row],[Canto]],"""",", subtitle: ","""",Table1[[#This Row],[subtitle]],"""",", ","category: ","""",Table1[[#This Row],[Categoria]],"""",", moments: [","""",Table1[[#This Row],[Adviento]],""",","""",Table1[[#This Row],[Navidad]],""",","""",Table1[[#This Row],[Cuaresma]],""",","""",Table1[[#This Row],[Pascua]],""",","""",Table1[[#This Row],[Pentecostés]],""",","""",Table1[[#This Row],[Entrada]],""",","""",Table1[[#This Row],[Virgen]],""",","""",Table1[[#This Row],[Paz]],""",","""",Table1[[#This Row],[Pan]],""",","""",Table1[[#This Row],[Comunión]],""",","""",Table1[[#This Row],[Niños]],""",","""",Table1[[#This Row],[Laudes]],""",","""",Table1[[#This Row],[Nuevo Testamento]],""",","""",Table1[[#This Row],[Antiguo Testamento]],""",","""",Table1[[#This Row],[Final]],"""","], url: ","""",Table1[[#This Row],[URL]],"""","},") -> {id:6,title: "A ti, Señor, levanto mi alma", subtitle: "Salmo 25 (24)", category: "Precatecumenado", moments: ["","","Cuaresma","","","","","","","","","","","Antiguo Testamento",""], url: "/cantos/src/chtml/a/atisenorlevantomialma.html"},
A9: 6 | B9: 7 | C9: A ti, Señor, se debe la alabanza en Sión | D9: Salmo 65 (64) | E9: =LOWER(LEFT(Table1[[#This Row],[Canto]],1)) -> a | F9: Precatecumenado | G9: =IFERROR(IF(VLOOKUP(C9,Adviento!A:C,3,FALSE)=Table1[[#Headers],[Adviento]],Table1[[#Headers],[Adviento]],""),"") | H9: =IFERROR(IF(VLOOKUP(C9,Navidad!A:C,3,FALSE)=Table1[[#Headers],[Navidad]],Table1[[#Headers],[Navidad]],""),"") | I9: =IFERROR(IF(VLOOKUP(C9,Cuaresma!A:C,3,FALSE)=Table1[[#Headers],[Cuaresma]],Table1[[#Headers],[Cuaresma]],""),"") -> Cuaresma | J9: =IFERROR(IF(VLOOKUP(C9,Pascua!A:C,3,FALSE)=Table1[[#Headers],[Pascua]],Table1[[#Headers],[Pascua]],""),"") | K9: =IFERROR(IF(VLOOKUP(C9,Pentecostés!A:C,3,FALSE)=Table1[[#Headers],[Pentecostés]],Table1[[#Headers],[Pentecostés]],""),"") | L9: =IFERROR(IF(VLOOKUP(C9,Entrada!A:C,3,FALSE)=Table1[[#Headers],[Entrada]],Table1[[#Headers],[Entrada]],""),"") | M9: =IFERROR(IF(VLOOKUP(C9,Virgen!A:C,3,FALSE)=Table1[[#Headers],[Virgen]],Table1[[#Headers],[Virgen]],""),"") | N9: =IFERROR(IF(VLOOKUP(C9,Paz!A:C,3,FALSE)=Table1[[#Headers],[Paz]],Table1[[#Headers],[Paz]],""),"") | O9: =IFERROR(IF(VLOOKUP(C9,Pan!A:C,3,FALSE)=Table1[[#Headers],[Pan]],Table1[[#Headers],[Pan]],""),"") | P9: =IFERROR(IF(VLOOKUP(C9,Comunión!A:C,3,FALSE)=Table1[[#Headers],[Comunión]],Table1[[#Headers],[Comunión]],""),"") | Q9: =IFERROR(IF(VLOOKUP(C9,Niños!A:C,3,FALSE)=Table1[[#Headers],[Niños]],Table1[[#Headers],[Niños]],""),"") | R9: =IFERROR(IF(VLOOKUP(C9,Laudes!A:C,3,FALSE)=Table1[[#Headers],[Laudes]],Table1[[#Headers],[Laudes]],""),"") -> Laudes | S9: =IFERROR(IF(VLOOKUP(C9,'Nuevo Testamento'!A:C,3,FALSE)=Table1[[#Headers],[Nuevo Testamento]],Table1[[#Headers],[Nuevo Testamento]],""),"") | T9: =IFERROR(IF(VLOOKUP(C9,'Antiguo Testamento'!A:C,3,FALSE)=Table1[[#Headers],[Antiguo Testamento]],Table1[[#Headers],[Antiguo Testamento]],""),"") -> Antiguo Testamento | U9: =IFERROR(IF(VLOOKUP(C9,Final!A:C,3,FALSE)=Table1[[#Headers],[Final]],Table1[[#Headers],[Final]],""),"") | V9: {=_xlfn.LET( _xlpm.texto_limpio, _xlfn.REDUCE( LOWER(Table1[[#This Row],[Canto]]), {"á";"é";"í";"ó";"ú";"ñ";",";" "}, _xlfn.LAMBDA(_xlpm.acum,_xlpm.caracter, SUBSTITUTE(_xlpm.acum, _xlpm.caracter, CHOOSE(MATCH(_xlpm.caracter, {"á";"é";"í";"ó";"ú";"ñ";",";" "}, 0), "a","e","i","o","u","n","",""))) ), _xlfn.CONCAT("/cantos/src/chtml/", Table1[[#This Row],[iniciar]], "/", _xlpm.texto_limpio, ".html") )} -> /cantos/src/chtml/a/atisenorsedebelaalabanzaension.html | W9: =_xlfn.CONCAT("{id:",Table1[[#This Row],[Or'#]],",","title: ","""",Table1[[#This Row],[Canto]],"""",", subtitle: ","""",Table1[[#This Row],[subtitle]],"""",", ","category: ","""",Table1[[#This Row],[Categoria]],"""",", moments: [","""",Table1[[#This Row],[Adviento]],""",","""",Table1[[#This Row],[Navidad]],""",","""",Table1[[#This Row],[Cuaresma]],""",","""",Table1[[#This Row],[Pascua]],""",","""",Table1[[#This Row],[Pentecostés]],""",","""",Table1[[#This Row],[Entrada]],""",","""",Table1[[#This Row],[Virgen]],""",","""",Table1[[#This Row],[Paz]],""",","""",Table1[[#This Row],[Pan]],""",","""",Table1[[#This Row],[Comunión]],""",","""",Table1[[#This Row],[Niños]],""",","""",Table1[[#This Row],[Laudes]],""",","""",Table1[[#This Row],[Nuevo Testamento]],""",","""",Table1[[#This Row],[Antiguo Testamento]],""",","""",Table1[[#This Row],[Final]],"""","], url: ","""",Table1[[#This Row],[URL]],"""","},") -> {id:7,title: "A ti, Señor, se debe la alabanza en Sión", subtitle: "Salmo 65 (64)", category: "Precatecumenado", moments: ["","","Cuaresma","","","","","","","","","Laudes","","Antiguo Testamento",""], url: "/cantos/src/chtml/a/atisenorsedebelaalabanzaension.html"},
A10: 7 | B10: 8 | C10: Abbá, Padre | D10: Romanos 8,15–17 | E10: =LOWER(LEFT(Table1[[#This Row],[Canto]],1)) -> a | F10: Precatecumenado | G10: =IFERROR(IF(VLOOKUP(C10,Adviento!A:C,3,FALSE)=Table1[[#Headers],[Adviento]],Table1[[#Headers],[Adviento]],""),"") | H10: =IFERROR(IF(VLOOKUP(C10,Navidad!A:C,3,FALSE)=Table1[[#Headers],[Navidad]],Table1[[#Headers],[Navidad]],""),"") | I10: =IFERROR(IF(VLOOKUP(C10,Cuaresma!A:C,3,FALSE)=Table1[[#Headers],[Cuaresma]],Table1[[#Headers],[Cuaresma]],""),"") | J10: =IFERROR(IF(VLOOKUP(C10,Pascua!A:C,3,FALSE)=Table1[[#Headers],[Pascua]],Table1[[#Headers],[Pascua]],""),"") -> Pascua | K10: =IFERROR(IF(VLOOKUP(C10,Pentecostés!A:C,3,FALSE)=Table1[[#Headers],[Pentecostés]],Table1[[#Headers],[Pentecostés]],""),"") -> Pentecostés | L10: =IFERROR(IF(VLOOKUP(C10,Entrada!A:C,3,FALSE)=Table1[[#Headers],[Entrada]],Table1[[#Headers],[Entrada]],""),"") -> Entrada | M10: =IFERROR(IF(VLOOKUP(C10,Virgen!A:C,3,FALSE)=Table1[[#Headers],[Virgen]],Table1[[#Headers],[Virgen]],""),"") | N10: =IFERROR(IF(VLOOKUP(C10,Paz!A:C,3,FALSE)=Table1[[#Headers],[Paz]],Table1[[#Headers],[Paz]],""),"") | O10: =IFERROR(IF(VLOOKUP(C10,Pan!A:C,3,FALSE)=Table1[[#Headers],[Pan]],Table1[[#Headers],[Pan]],""),"") | P10: =IFERROR(IF(VLOOKUP(C10,Comunión!A:C,3,FALSE)=Table1[[#Headers],[Comunión]],Table1[[#Headers],[Comunión]],""),"") | Q10: =IFERROR(IF(VLOOKUP(C10,Niños!A:C,3,FALSE)=Table1[[#Headers],[Niños]],Table1[[#Headers],[Niños]],""),"") | R10: =IFERROR(IF(VLOOKUP(C10,Laudes!A:C,3,FALSE)=Table1[[#Headers],[Laudes]],Table1[[#Headers],[Laudes]],""),"") -> Laudes | S10: =IFERROR(IF(VLOOKUP(C10,'Nuevo Testamento'!A:C,3,FALSE)=Table1[[#Headers],[Nuevo Testamento]],Table1[[#Headers],[Nuevo Testamento]],""),"") -> Nuevo Testamento | T10: =IFERROR(IF(VLOOKUP(C10,'Antiguo Testamento'!A:C,3,FALSE)=Table1[[#Headers],[Antiguo Testamento]],Table1[[#Headers],[Antiguo Testamento]],""),"") | U10: =IFERROR(IF(VLOOKUP(C10,Final!A:C,3,FALSE)=Table1[[#Headers],[Final]],Table1[[#Headers],[Final]],""),"") | V10: {=_xlfn.LET( _xlpm.texto_limpio, _xlfn.REDUCE( LOWER(Table1[[#This Row],[Canto]]), {"á";"é";"í";"ó";"ú";"ñ";",";" "}, _xlfn.LAMBDA(_xlpm.acum,_xlpm.caracter, SUBSTITUTE(_xlpm.acum, _xlpm.caracter, CHOOSE(MATCH(_xlpm.caracter, {"á";"é";"í";"ó";"ú";"ñ";",";" "}, 0), "a","e","i","o","u","n","",""))) ), _xlfn.CONCAT("/cantos/src/chtml/", Table1[[#This Row],[iniciar]], "/", _xlpm.texto_limpio, ".html") )} -> /cantos/src/chtml/a/abbapadre.html | W10: =_xlfn.CONCAT("{id:",Table1[[#This Row],[Or'#]],",","title: ","""",Table1[[#This Row],[Canto]],"""",", subtitle: ","""",Table1[[#This Row],[subtitle]],"""",", ","category: ","""",Table1[[#This Row],[Categoria]],"""",", moments: [","""",Table1[[#This Row],[Adviento]],""",","""",Table1[[#This Row],[Navidad]],""",","""",Table1[[#This Row],[Cuaresma]],""",","""",Table1[[#This Row],[Pascua]],""",","""",Table1[[#This Row],[Pentecostés]],""",","""",Table1[[#This Row],[Entrada]],""",","""",Table1[[#This Row],[Virgen]],""",","""",Table1[[#This Row],[Paz]],""",","""",Table1[[#This Row],[Pan]],""",","""",Table1[[#This Row],[Comunión]],""",","""",Table1[[#This Row],[Niños]],""",","""",Table1[[#This Row],[Laudes]],""",","""",Table1[[#This Row],[Nuevo Testamento]],""",","""",Table1[[#This Row],[Antiguo Testamento]],""",","""",Table1[[#This Row],[Final]],"""","], url: ","""",Table1[[#This Row],[URL]],"""","},") -> {id:8,title: "Abbá, Padre", subtitle: "Romanos 8,15–17", category: "Precatecumenado", moments: ["","","","Pascua","Pentecostés","Entrada","","","","","","Laudes","Nuevo Testamento","",""], url: "/cantos/src/chtml/a/abbapadre.html"},
A11: 8 | B11: 9 | C11: Abraham | D11: Génesis 18,1–5 – Teofanía de Mambré | E11: =LOWER(LEFT(Table1[[#This Row],[Canto]],1)) -> a | F11: Precatecumenado | G11: =IFERROR(IF(VLOOKUP(C11,Adviento!A:C,3,FALSE)=Table1[[#Headers],[Adviento]],Table1[[#Headers],[Adviento]],""),"") | H11: =IFERROR(IF(VLOOKUP(C11,Navidad!A:C,3,FALSE)=Table1[[#Headers],[Navidad]],Table1[[#Headers],[Navidad]],""),"") | I11: =IFERROR(IF(VLOOKUP(C11,Cuaresma!A:C,3,FALSE)=Table1[[#Headers],[Cuaresma]],Table1[[#Headers],[Cuaresma]],""),"") | J11: =IFERROR(IF(VLOOKUP(C11,Pascua!A:C,3,FALSE)=Table1[[#Headers],[Pascua]],Table1[[#Headers],[Pascua]],""),"") | K11: =IFERROR(IF(VLOOKUP(C11,Pentecostés!A:C,3,FALSE)=Table1[[#Headers],[Pentecostés]],Table1[[#Headers],[Pentecostés]],""),"") | L11: =IFERROR(IF(VLOOKUP(C11,Entrada!A:C,3,FALSE)=Table1[[#Headers],[Entrada]],Table1[[#Headers],[Entrada]],""),"") -> Entrada | M11: =IFERROR(IF(VLOOKUP(C11,Virgen!A:C,3,FALSE)=Table1[[#Headers],[Virgen]],Table1[[#Headers],[Virgen]],""),"") | N11: =IFERROR(IF(VLOOKUP(C11,Paz!A:C,3,FALSE)=Table1[[#Headers],[Paz]],Table1[[#Headers],[Paz]],""),"") | O11: =IFERROR(IF(VLOOKUP(C11,Pan!A:C,3,FALSE)=Table1[[#Headers],[Pan]],Table1[[#Headers],[Pan]],""),"") | P11: =IFERROR(IF(VLOOKUP(C11,Comunión!A:C,3,FALSE)=Table1[[#Headers],[Comunión]],Table1[[#Headers],[Comunión]],""),"") | Q11: =IFERROR(IF(VLOOKUP(C11,Niños!A:C,3,FALSE)=Table1[[#Headers],[Niños]],Table1[[#Headers],[Niños]],""),"") | R11: =IFERROR(IF(VLOOKUP(C11,Laudes!A:C,3,FALSE)=Table1[[#Headers],[Laudes]],Table1[[#Headers],[Laudes]],""),"") -> Laudes | S11: =IFERROR(IF(VLOOKUP(C11,'Nuevo Testamento'!A:C,3,FALSE)=Table1[[#Headers],[Nuevo Testamento]],Table1[[#Headers],[Nuevo Testamento]],""),"") | T11: =IFERROR(IF(VLOOKUP(C11,'Antiguo Testamento'!A:C,3,FALSE)=Table1[[#Headers],[Antiguo Testamento]],Table1[[#Headers],[Antiguo Testamento]],""),"") -> Antiguo Testamento | U11: =IFERROR(IF(VLOOKUP(C11,Final!A:C,3,FALSE)=Table1[[#Headers],[Final]],Table1[[#Headers],[Final]],""),"") | V11: {=_xlfn.LET( _xlpm.texto_limpio, _xlfn.REDUCE( LOWER(Table1[[#This Row],[Canto]]), {"á";"é";"í";"ó";"ú";"ñ";",";" "}, _xlfn.LAMBDA(_xlpm.acum,_xlpm.caracter, SUBSTITUTE(_xlpm.acum, _xlpm.caracter, CHOOSE(MATCH(_xlpm.caracter, {"á";"é";"í";"ó";"ú";"ñ";",";" "}, 0), "a","e","i","o","u","n","",""))) ), _xlfn.CONCAT("/cantos/src/chtml/", Table1[[#This Row],[iniciar]], "/", _xlpm.texto_limpio, ".html") )} -> /cantos/src/chtml/a/abraham.html | W11: =_xlfn.CONCAT("{id:",Table1[[#This Row],[Or'#]],",","title: ","""",Table1[[#This Row],[Canto]],"""",", subtitle: ","""",Table1[[#This Row],[subtitle]],"""",", ","category: ","""",Table1[[#This Row],[Categoria]],"""",", moments: [","""",Table1[[#This Row],[Adviento]],""",","""",Table1[[#This Row],[Navidad]],""",","""",Table1[[#This Row],[Cuaresma]],""",","""",Table1[[#This Row],[Pascua]],""",","""",Table1[[#This Row],[Pentecostés]],""",","""",Table1[[#This Row],[Entrada]],""",","""",Table1[[#This Row],[Virgen]],""",","""",Table1[[#This Row],[Paz]],""",","""",Table1[[#This Row],[Pan]],""",","""",Table1[[#This Row],[Comunión]],""",","""",Table1[[#This Row],[Niños]],""",","""",Table1[[#This Row],[Laudes]],""",","""",Table1[[#This Row],[Nuevo Testamento]],""",","""",Table1[[#This Row],[Antiguo Testamento]],""",","""",Table1[[#This Row],[Final]],"""","], url: ","""",Table1[[#This Row],[URL]],"""","},") -> {id:9,title: "Abraham", subtitle: "Génesis 18,1–5 – Teofanía de Mambré", category: "Precatecumenado", moments: ["","","","","","Entrada","","","","","","Laudes","","Antiguo Testamento",""], url: "/cantos/src/chtml/a/abraham.html"},
A12: 179 | B12: 10 | C12: Aclamaciones a la oración de los fieles | D12: Respuestas a las oraciones de los fieles, Modelo I, II, III, IV | E12: =LOWER(LEFT(Table1[[#This Row],[Canto]],1)) -> a | F12: Liturgia | G12: =IFERROR(IF(VLOOKUP(C12,Adviento!A:C,3,FALSE)=Table1[[#Headers],[Adviento]],Table1[[#Headers],[Adviento]],""),"") | H12: =IFERROR(IF(VLOOKUP(C12,Navidad!A:C,3,FALSE)=Table1[[#Headers],[Navidad]],Table1[[#Headers],[Navidad]],""),"") | I12: =IFERROR(IF(VLOOKUP(C12,Cuaresma!A:C,3,FALSE)=Table1[[#Headers],[Cuaresma]],Table1[[#Headers],[Cuaresma]],""),"") | J12: =IFERROR(IF(VLOOKUP(C12,Pascua!A:C,3,FALSE)=Table1[[#Headers],[Pascua]],Table1[[#Headers],[Pascua]],""),"") | K12: =IFERROR(IF(VLOOKUP(C12,Pentecostés!A:C,3,FALSE)=Table1[[#Headers],[Pentecostés]],Table1[[#Headers],[Pentecostés]],""),"") | L12: =IFERROR(IF(VLOOKUP(C12,Entrada!A:C,3,FALSE)=Table1[[#Headers],[Entrada]],Table1[[#Headers],[Entrada]],""),"") | M12: =IFERROR(IF(VLOOKUP(C12,Virgen!A:C,3,FALSE)=Table1[[#Headers],[Virgen]],Table1[[#Headers],[Virgen]],""),"") | N12: =IFERROR(IF(VLOOKUP(C12,Paz!A:C,3,FALSE)=Table1[[#Headers],[Paz]],Table1[[#Headers],[Paz]],""),"") | O12: =IFERROR(IF(VLOOKUP(C12,Pan!A:C,3,FALSE)=Table1[[#Headers],[Pan]],Table1[[#Headers],[Pan]],""),"") | P12: =IFERROR(IF(VLOOKUP(C12,Comunión!A:C,3,FALSE)=Table1[[#Headers],[Comunión]],Table1[[#Headers],[Comunión]],""),"") | Q12: =IFERROR(IF(VLOOKUP(C12,Niños!A:C,3,FALSE)=Table1[[#Headers],[Niños]],Table1[[#Headers],[Niños]],""),"") | R12: =IFERROR(IF(VLOOKUP(C12,Laudes!A:C,3,FALSE)=Table1[[#Headers],[Laudes]],Table1[[#Headers],[Laudes]],""),"") | S12: =IFERROR(IF(VLOOKUP(C12,'Nuevo Testamento'!A:C,3,FALSE)=Table1[[#Headers],[Nuevo Testamento]],Table1[[#Headers],[Nuevo Testamento]],""),"") | T12: =IFERROR(IF(VLOOKUP(C12,'Antiguo Testamento'!A:C,3,FALSE)=Table1[[#Headers],[Antiguo Testamento]],Table1[[#Headers],[Antiguo Testamento]],""),"") | U12: =IFERROR(IF(VLOOKUP(C12,Final!A:C,3,FALSE)=Table1[[#Headers],[Final]],Table1[[#Headers],[Final]],""),"") | V12: {=_xlfn.LET( _xlpm.texto_limpio, _xlfn.REDUCE( LOWER(Table1[[#This Row],[Canto]]), {"á";"é";"í";"ó";"ú";"ñ";",";" "}, _xlfn.LAMBDA(_xlpm.acum,_xlpm.caracter, SUBSTITUTE(_xlpm.acum, _xlpm.caracter, CHOOSE(MATCH(_xlpm.caracter, {"á";"é";"í";"ó";"ú";"ñ";",";" "}, 0), "a","e","i","o","u","n","",""))) ), _xlfn.CONCAT("/cantos/src/chtml/", Table1[[#This Row],[iniciar]], "/", _xlpm.texto_limpio, ".html") )} -> /cantos/src/chtml/a/aclamacionesalaoraciondelosfieles.html | W12: =_xlfn.CONCAT("{id:",Table1[[#This Row],[Or'#]],",","title: ","""",Table1[[#This Row],[Canto]],"""",", subtitle: ","""",Table1[[#This Row],[subtitle]],"""",", ","category: ","""",Table1[[#This Row],[Categoria]],"""",", moments: [","""",Table1[[#This Row],[Adviento]],""",","""",Table1[[#This Row],[Navidad]],""",","""",Table1[[#This Row],[Cuaresma]],""",","""",Table1[[#This Row],[Pascua]],""",","""",Table1[[#This Row],[Pentecostés]],""",","""",Table1[[#This Row],[Entrada]],""",","""",Table1[[#This Row],[Virgen]],""",","""",Table1[[#This Row],[Paz]],""",","""",Table1[[#This Row],[Pan]],""",","""",Table1[[#This Row],[Comunión]],""",","""",Table1[[#This Row],[Niños]],""",","""",Table1[[#This Row],[Laudes]],""",","""",Table1[[#This Row],[Nuevo Testamento]],""",","""",Table1[[#This Row],[Antiguo Testamento]],""",","""",Table1[[#This Row],[Final]],"""","], url: ","""",Table1[[#This Row],[URL]],"""","},") -> {id:10,title: "Aclamaciones a la oración de los fieles", subtitle: "Respuestas a las oraciones de los fieles, Modelo I, II, III, IV", category: "Liturgia", moments: ["","","","","","","","","","","","","","",""], url: "/cantos/src/chtml/a/aclamacionesalaoraciondelosfieles.html"},
A13: 9 | B13: 11 | C13: Aclamad al Señor | D13: Salmo 100 (99) | E13: =LOWER(LEFT(Table1[[#This Row],[Canto]],1)) -> a | F13: Precatecumenado | G13: =IFERROR(IF(VLOOKUP(C13,Adviento!A:C,3,FALSE)=Table1[[#Headers],[Adviento]],Table1[[#Headers],[Adviento]],""),"") | H13: =IFERROR(IF(VLOOKUP(C13,Navidad!A:C,3,FALSE)=Table1[[#Headers],[Navidad]],Table1[[#Headers],[Navidad]],""),"") | I13: =IFERROR(IF(VLOOKUP(C13,Cuaresma!A:C,3,FALSE)=Table1[[#Headers],[Cuaresma]],Table1[[#Headers],[Cuaresma]],""),"") | J13: =IFERROR(IF(VLOOKUP(C13,Pascua!A:C,3,FALSE)=Table1[[#Headers],[Pascua]],Table1[[#Headers],[Pascua]],""),"") | K13: =IFERROR(IF(VLOOKUP(C13,Pentecostés!A:C,3,FALSE)=Table1[[#Headers],[Pentecostés]],Table1[[#Headers],[Pentecostés]],""),"") | L13: =IFERROR(IF(VLOOKUP(C13,Entrada!A:C,3,FALSE)=Table1[[#Headers],[Entrada]],Table1[[#Headers],[Entrada]],""),"") -> Entrada | M13: =IFERROR(IF(VLOOKUP(C13,Virgen!A:C,3,FALSE)=Table1[[#Headers],[Virgen]],Table1[[#Headers],[Virgen]],""),"") | N13: =IFERROR(IF(VLOOKUP(C13,Paz!A:C,3,FALSE)=Table1[[#Headers],[Paz]],Table1[[#Headers],[Paz]],""),"") | O13: =IFERROR(IF(VLOOKUP(C13,Pan!A:C,3,FALSE)=Table1[[#Headers],[Pan]],Table1[[#Headers],[Pan]],""),"") | P13: =IFERROR(IF(VLOOKUP(C13,Comunión!A:C,3,FALSE)=Table1[[#Headers],[Comunión]],Table1[[#Headers],[Comunión]],""),"") | Q13: =IFERROR(IF(VLOOKUP(C13,Niños!A:C,3,FALSE)=Table1[[#Headers],[Niños]],Table1[[#Headers],[Niños]],""),"") | R13: =IFERROR(IF(VLOOKUP(C13,Laudes!A:C,3,FALSE)=Table1[[#Headers],[Laudes]],Table1[[#Headers],[Laudes]],""),"") -> Laudes | S13: =IFERROR(IF(VLOOKUP(C13,'Nuevo Testamento'!A:C,3,FALSE)=Table1[[#Headers],[Nuevo Testamento]],Table1[[#Headers],[Nuevo Testamento]],""),"") | T13: =IFERROR(IF(VLOOKUP(C13,'Antiguo Testamento'!A:C,3,FALSE)=Table1[[#Headers],[Antiguo Testamento]],Table1[[#Headers],[Antiguo Testamento]],""),"") -> Antiguo Testamento | U13: =IFERROR(IF(VLOOKUP(C13,Final!A:C,3,FALSE)=Table1[[#Headers],[Final]],Table1[[#Headers],[Final]],""),"") | V13: {=_xlfn.LET( _xlpm.texto_limpio, _xlfn.REDUCE( LOWER(Table1[[#This Row],[Canto]]), {"á";"é";"í";"ó";"ú";"ñ";",";" "}, _xlfn.LAMBDA(_xlpm.acum,_xlpm.caracter, SUBSTITUTE(_xlpm.acum, _xlpm.caracter, CHOOSE(MATCH(_xlpm.caracter, {"á";"é";"í";"ó";"ú";"ñ";",";" "}, 0), "a","e","i","o","u","n","",""))) ), _xlfn.CONCAT("/cantos/src/chtml/", Table1[[#This Row],[iniciar]], "/", _xlpm.texto_limpio, ".html") )} -> /cantos/src/chtml/a/aclamadalsenor.html | W13: =_xlfn.CONCAT("{id:",Table1[[#This Row],[Or'#]],",","title: ","""",Table1[[#This Row],[Canto]],"""",", subtitle: ","""",Table1[[#This Row],[subtitle]],"""",", ","category: ","""",Table1[[#This Row],[Categoria]],"""",", moments: [","""",Table1[[#This Row],[Adviento]],""",","""",Table1[[#This Row],[Navidad]],""",","""",Table1[[#This Row],[Cuaresma]],""",","""",Table1[[#This Row],[Pascua]],""",","""",Table1[[#This Row],[Pentecostés]],""",","""",Table1[[#This Row],[Entrada]],""",","""",Table1[[#This Row],[Virgen]],""",","""",Table1[[#This Row],[Paz]],""",","""",Table1[[#This Row],[Pan]],""",","""",Table1[[#This Row],[Comunión]],""",","""",Table1[[#This Row],[Niños]],""",","""",Table1[[#This Row],[Laudes]],""",","""",Table1[[#This Row],[Nuevo Testamento]],""",","""",Table1[[#This Row],[Antiguo Testamento]],""",","""",Table1[[#This Row],[Final]],"""","], url: ","""",Table1[[#This Row],[URL]],"""","},") -> {id:11,title: "Aclamad al Señor", subtitle: "Salmo 100 (99)", category: "Precatecumenado", moments: ["","","","","","Entrada","","","","","","Laudes","","Antiguo Testamento",""], url: "/cantos/src/chtml/a/aclamadalsenor.html"},
A14: 238 | B14: 12 | C14: Adónde te escondiste, Amado | D14: Cántico espiritual (San Juan de la Cruz) | E14: =LOWER(LEFT(Table1[[#This Row],[Canto]],1)) -> a | F14: Eleccion | G14: =IFERROR(IF(VLOOKUP(C14,Adviento!A:C,3,FALSE)=Table1[[#Headers],[Adviento]],Table1[[#Headers],[Adviento]],""),"") | H14: =IFERROR(IF(VLOOKUP(C14,Navidad!A:C,3,FALSE)=Table1[[#Headers],[Navidad]],Table1[[#Headers],[Navidad]],""),"") | I14: =IFERROR(IF(VLOOKUP(C14,Cuaresma!A:C,3,FALSE)=Table1[[#Headers],[Cuaresma]],Table1[[#Headers],[Cuaresma]],""),"") | J14: =IFERROR(IF(VLOOKUP(C14,Pascua!A:C,3,FALSE)=Table1[[#Headers],[Pascua]],Table1[[#Headers],[Pascua]],""),"") | K14: =IFERROR(IF(VLOOKUP(C14,Pentecostés!A:C,3,FALSE)=Table1[[#Headers],[Pentecostés]],Table1[[#Headers],[Pentecostés]],""),"") | L14: =IFERROR(IF(VLOOKUP(C14,Entrada!A:C,3,FALSE)=Table1[[#Headers],[Entrada]],Table1[[#Headers],[Entrada]],""),"") | M14: =IFERROR(IF(VLOOKUP(C14,Virgen!A:C,3,FALSE)=Table1[[#Headers],[Virgen]],Table1[[#Headers],[Virgen]],""),"") | N14: =IFERROR(IF(VLOOKUP(C14,Paz!A:C,3,FALSE)=Table1[[#Headers],[Paz]],Table1[[#Headers],[Paz]],""),"") | O14: =IFERROR(IF(VLOOKUP(C14,Pan!A:C,3,FALSE)=Table1[[#Headers],[Pan]],Table1[[#Headers],[Pan]],""),"") | P14: =IFERROR(IF(VLOOKUP(C14,Comunión!A:C,3,FALSE)=Table1[[#Headers],[Comunión]],Table1[[#Headers],[Comunión]],""),"") | Q14: =IFERROR(IF(VLOOKUP(C14,Niños!A:C,3,FALSE)=Table1[[#Headers],[Niños]],Table1[[#Headers],[Niños]],""),"") | R14: =IFERROR(IF(VLOOKUP(C14,Laudes!A:C,3,FALSE)=Table1[[#Headers],[Laudes]],Table1[[#Headers],[Laudes]],""),"") | S14: =IFERROR(IF(VLOOKUP(C14,'Nuevo Testamento'!A:C,3,FALSE)=Table1[[#Headers],[Nuevo Testamento]],Table1[[#Headers],[Nuevo Testamento]],""),"") | T14: =IFERROR(IF(VLOOKUP(C14,'Antiguo Testamento'!A:C,3,FALSE)=Table1[[#Headers],[Antiguo Testamento]],Table1[[#Headers],[Antiguo Testamento]],""),"") | U14: =IFERROR(IF(VLOOKUP(C14,Final!A:C,3,FALSE)=Table1[[#Headers],[Final]],Table1[[#Headers],[Final]],""),"") | V14: {=_xlfn.LET( _xlpm.texto_limpio, _xlfn.REDUCE( LOWER(Table1[[#This Row],[Canto]]), {"á";"é";"í";"ó";"ú";"ñ";",";" "}, _xlfn.LAMBDA(_xlpm.acum,_xlpm.caracter, SUBSTITUTE(_xlpm.acum, _xlpm.caracter, CHOOSE(MATCH(_xlpm.caracter, {"á";"é";"í";"ó";"ú";"ñ";",";" "}, 0), "a","e","i","o","u","n","",""))) ), _xlfn.CONCAT("/cantos/src/chtml/", Table1[[#This Row],[iniciar]], "/", _xlpm.texto_limpio, ".html") )} -> /cantos/src/chtml/a/adondeteescondisteamado.html | W14: =_xlfn.CONCAT("{id:",Table1[[#This Row],[Or'#]],",","title: ","""",Table1[[#This Row],[Canto]],"""",", subtitle: ","""",Table1[[#This Row],[subtitle]],"""",", ","category: ","""",Table1[[#This Row],[Categoria]],"""",", moments: [","""",Table1[[#This Row],[Adviento]],""",","""",Table1[[#This Row],[Navidad]],""",","""",Table1[[#This Row],[Cuaresma]],""",","""",Table1[[#This Row],[Pascua]],""",","""",Table1[[#This Row],[Pentecostés]],""",","""",Table1[[#This Row],[Entrada]],""",","""",Table1[[#This Row],[Virgen]],""",","""",Table1[[#This Row],[Paz]],""",","""",Table1[[#This Row],[Pan]],""",","""",Table1[[#This Row],[Comunión]],""",","""",Table1[[#This Row],[Niños]],""",","""",Table1[[#This Row],[Laudes]],""",","""",Table1[[#This Row],[Nuevo Testamento]],""",","""",Table1[[#This Row],[Antiguo Testamento]],""",","""",Table1[[#This Row],[Final]],"""","], url: ","""",Table1[[#This Row],[URL]],"""","},") -> {id:12,title: "Adónde te escondiste, Amado", subtitle: "Cántico espiritual (San Juan de la Cruz) ", category: "Eleccion", moments: ["","","","","","","","","","","","","","",""], url: "/cantos/src/chtml/a/adondeteescondisteamado.html"},
... A192: 216 | B192: 190 | C192: Santo Palestina 74 | D192: Roma 77 | E192: =LOWER(LEFT(Table1[[#This Row],[Canto]],1)) -> s | F192: Liturgia | G192: =IFERROR(IF(VLOOKUP(C192,Adviento!A:C,3,FALSE)=Table1[[#Headers],[Adviento]],Table1[[#Headers],[Adviento]],""),"") | H192: =IFERROR(IF(VLOOKUP(C192,Navidad!A:C,3,FALSE)=Table1[[#Headers],[Navidad]],Table1[[#Headers],[Navidad]],""),"") | I192: =IFERROR(IF(VLOOKUP(C192,Cuaresma!A:C,3,FALSE)=Table1[[#Headers],[Cuaresma]],Table1[[#Headers],[Cuaresma]],""),"") | J192: =IFERROR(IF(VLOOKUP(C192,Pascua!A:C,3,FALSE)=Table1[[#Headers],[Pascua]],Table1[[#Headers],[Pascua]],""),"") | K192: =IFERROR(IF(VLOOKUP(C192,Pentecostés!A:C,3,FALSE)=Table1[[#Headers],[Pentecostés]],Table1[[#Headers],[Pentecostés]],""),"") | L192: =IFERROR(IF(VLOOKUP(C192,Entrada!A:C,3,FALSE)=Table1[[#Headers],[Entrada]],Table1[[#Headers],[Entrada]],""),"") | M192: =IFERROR(IF(VLOOKUP(C192,Virgen!A:C,3,FALSE)=Table1[[#Headers],[Virgen]],Table1[[#Headers],[Virgen]],""),"") | N192: =IFERROR(IF(VLOOKUP(C192,Paz!A:C,3,FALSE)=Table1[[#Headers],[Paz]],Table1[[#Headers],[Paz]],""),"") | O192: =IFERROR(IF(VLOOKUP(C192,Pan!A:C,3,FALSE)=Table1[[#Headers],[Pan]],Table1[[#Headers],[Pan]],""),"") | P192: =IFERROR(IF(VLOOKUP(C192,Comunión!A:C,3,FALSE)=Table1[[#Headers],[Comunión]],Table1[[#Headers],[Comunión]],""),"") | Q192: =IFERROR(IF(VLOOKUP(C192,Niños!A:C,3,FALSE)=Table1[[#Headers],[Niños]],Table1[[#Headers],[Niños]],""),"") | R192: =IFERROR(IF(VLOOKUP(C192,Laudes!A:C,3,FALSE)=Table1[[#Headers],[Laudes]],Table1[[#Headers],[Laudes]],""),"") | S192: =IFERROR(IF(VLOOKUP(C192,'Nuevo Testamento'!A:C,3,FALSE)=Table1[[#Headers],[Nuevo Testamento]],Table1[[#Headers],[Nuevo Testamento]],""),"") | T192: =IFERROR(IF(VLOOKUP(C192,'Antiguo Testamento'!A:C,3,FALSE)=Table1[[#Headers],[Antiguo Testamento]],Table1[[#Headers],[Antiguo Testamento]],""),"") | U192: =IFERROR(IF(VLOOKUP(C192,Final!A:C,3,FALSE)=Table1[[#Headers],[Final]],Table1[[#Headers],[Final]],""),"") | V192: {=_xlfn.LET( _xlpm.texto_limpio, _xlfn.REDUCE( LOWER(Table1[[#This Row],[Canto]]), {"á";"é";"í";"ó";"ú";"ñ";",";" "}, _xlfn.LAMBDA(_xlpm.acum,_xlpm.caracter, SUBSTITUTE(_xlpm.acum, _xlpm.caracter, CHOOSE(MATCH(_xlpm.caracter, {"á";"é";"í";"ó";"ú";"ñ";",";" "}, 0), "a","e","i","o","u","n","",""))) ), _xlfn.CONCAT("/cantos/src/chtml/", Table1[[#This Row],[iniciar]], "/", _xlpm.texto_limpio, ".html") )} -> /cantos/src/chtml/s/santopalestina74.html | W192: =_xlfn.CONCAT("{id:",Table1[[#This Row],[Or'#]],",","title: ","""",Table1[[#This Row],[Canto]],"""",", subtitle: ","""",Table1[[#This Row],[subtitle]],"""",", ","category: ","""",Table1[[#This Row],[Categoria]],"""",", moments: [","""",Table1[[#This Row],[Adviento]],""",","""",Table1[[#This Row],[Navidad]],""",","""",Table1[[#This Row],[Cuaresma]],""",","""",Table1[[#This Row],[Pascua]],""",","""",Table1[[#This Row],[Pentecostés]],""",","""",Table1[[#This Row],[Entrada]],""",","""",Table1[[#This Row],[Virgen]],""",","""",Table1[[#This Row],[Paz]],""",","""",Table1[[#This Row],[Pan]],""",","""",Table1[[#This Row],[Comunión]],""",","""",Table1[[#This Row],[Niños]],""",","""",Table1[[#This Row],[Laudes]],""",","""",Table1[[#This Row],[Nuevo Testamento]],""",","""",Table1[[#This Row],[Antiguo Testamento]],""",","""",Table1[[#This Row],[Final]],"""","], url: ","""",Table1[[#This Row],[URL]],"""","},") -> {id:190,title: "Santo Palestina 74", subtitle: "Roma 77", category: "Liturgia", moments: ["","","","","","","","","","","","","","",""], url: "/cantos/src/chtml/s/santopalestina74.html"},
A193: 214 | B193: 191 | C193: Santo Palomeras 65 | D193: 1982 | E193: =LOWER(LEFT(Table1[[#This Row],[Canto]],1)) -> s | F193: Liturgia | G193: =IFERROR(IF(VLOOKUP(C193,Adviento!A:C,3,FALSE)=Table1[[#Headers],[Adviento]],Table1[[#Headers],[Adviento]],""),"") | H193: =IFERROR(IF(VLOOKUP(C193,Navidad!A:C,3,FALSE)=Table1[[#Headers],[Navidad]],Table1[[#Headers],[Navidad]],""),"") | I193: =IFERROR(IF(VLOOKUP(C193,Cuaresma!A:C,3,FALSE)=Table1[[#Headers],[Cuaresma]],Table1[[#Headers],[Cuaresma]],""),"") | J193: =IFERROR(IF(VLOOKUP(C193,Pascua!A:C,3,FALSE)=Table1[[#Headers],[Pascua]],Table1[[#Headers],[Pascua]],""),"") | K193: =IFERROR(IF(VLOOKUP(C193,Pentecostés!A:C,3,FALSE)=Table1[[#Headers],[Pentecostés]],Table1[[#Headers],[Pentecostés]],""),"") | L193: =IFERROR(IF(VLOOKUP(C193,Entrada!A:C,3,FALSE)=Table1[[#Headers],[Entrada]],Table1[[#Headers],[Entrada]],""),"") | M193: =IFERROR(IF(VLOOKUP(C193,Virgen!A:C,3,FALSE)=Table1[[#Headers],[Virgen]],Table1[[#Headers],[Virgen]],""),"") | N193: =IFERROR(IF(VLOOKUP(C193,Paz!A:C,3,FALSE)=Table1[[#Headers],[Paz]],Table1[[#Headers],[Paz]],""),"") | O193: =IFERROR(IF(VLOOKUP(C193,Pan!A:C,3,FALSE)=Table1[[#Headers],[Pan]],Table1[[#Headers],[Pan]],""),"") | P193: =IFERROR(IF(VLOOKUP(C193,Comunión!A:C,3,FALSE)=Table1[[#Headers],[Comunión]],Table1[[#Headers],[Comunión]],""),"") | Q193: =IFERROR(IF(VLOOKUP(C193,Niños!A:C,3,FALSE)=Table1[[#Headers],[Niños]],Table1[[#Headers],[Niños]],""),"") | R193: =IFERROR(IF(VLOOKUP(C193,Laudes!A:C,3,FALSE)=Table1[[#Headers],[Laudes]],Table1[[#Headers],[Laudes]],""),"") | S193: =IFERROR(IF(VLOOKUP(C193,'Nuevo Testamento'!A:C,3,FALSE)=Table1[[#Headers],[Nuevo Testamento]],Table1[[#Headers],[Nuevo Testamento]],""),"") | T193: =IFERROR(IF(VLOOKUP(C193,'Antiguo Testamento'!A:C,3,FALSE)=Table1[[#Headers],[Antiguo Testamento]],Table1[[#Headers],[Antiguo Testamento]],""),"") | U193: =IFERROR(IF(VLOOKUP(C193,Final!A:C,3,FALSE)=Table1[[#Headers],[Final]],Table1[[#Headers],[Final]],""),"") | V193: {=_xlfn.LET( _xlpm.texto_limpio, _xlfn.REDUCE( LOWER(Table1[[#This Row],[Canto]]), {"á";"é";"í";"ó";"ú";"ñ";",";" "}, _xlfn.LAMBDA(_xlpm.acum,_xlpm.caracter, SUBSTITUTE(_xlpm.acum, _xlpm.caracter, CHOOSE(MATCH(_xlpm.caracter, {"á";"é";"í";"ó";"ú";"ñ";",";" "}, 0), "a","e","i","o","u","n","",""))) ), _xlfn.CONCAT("/cantos/src/chtml/", Table1[[#This Row],[iniciar]], "/", _xlpm.texto_limpio, ".html") )} -> /cantos/src/chtml/s/santopalomeras65.html | W193: =_xlfn.CONCAT("{id:",Table1[[#This Row],[Or'#]],",","title: ","""",Table1[[#This Row],[Canto]],"""",", subtitle: ","""",Table1[[#This Row],[subtitle]],"""",", ","category: ","""",Table1[[#This Row],[Categoria]],"""",", moments: [","""",Table1[[#This Row],[Adviento]],""",","""",Table1[[#This Row],[Navidad]],""",","""",Table1[[#This Row],[Cuaresma]],""",","""",Table1[[#This Row],[Pascua]],""",","""",Table1[[#This Row],[Pentecostés]],""",","""",Table1[[#This Row],[Entrada]],""",","""",Table1[[#This Row],[Virgen]],""",","""",Table1[[#This Row],[Paz]],""",","""",Table1[[#This Row],[Pan]],""",","""",Table1[[#This Row],[Comunión]],""",","""",Table1[[#This Row],[Niños]],""",","""",Table1[[#This Row],[Laudes]],""",","""",Table1[[#This Row],[Nuevo Testamento]],""",","""",Table1[[#This Row],[Antiguo Testamento]],""",","""",Table1[[#This Row],[Final]],"""","], url: ","""",Table1[[#This Row],[URL]],"""","},") -> {id:191,title: "Santo Palomeras 65", subtitle: "1982", category: "Liturgia", moments: ["","","","","","","","","","","","","","",""], url: "/cantos/src/chtml/s/santopalomeras65.html"},
A194: 217 | B194: 192 | C194: Santo Roma 77 | D194: 1988 | E194: =LOWER(LEFT(Table1[[#This Row],[Canto]],1)) -> s | F194: Liturgia | G194: =IFERROR(IF(VLOOKUP(C194,Adviento!A:C,3,FALSE)=Table1[[#Headers],[Adviento]],Table1[[#Headers],[Adviento]],""),"") | H194: =IFERROR(IF(VLOOKUP(C194,Navidad!A:C,3,FALSE)=Table1[[#Headers],[Navidad]],Table1[[#Headers],[Navidad]],""),"") | I194: =IFERROR(IF(VLOOKUP(C194,Cuaresma!A:C,3,FALSE)=Table1[[#Headers],[Cuaresma]],Table1[[#Headers],[Cuaresma]],""),"") | J194: =IFERROR(IF(VLOOKUP(C194,Pascua!A:C,3,FALSE)=Table1[[#Headers],[Pascua]],Table1[[#Headers],[Pascua]],""),"") | K194: =IFERROR(IF(VLOOKUP(C194,Pentecostés!A:C,3,FALSE)=Table1[[#Headers],[Pentecostés]],Table1[[#Headers],[Pentecostés]],""),"") | L194: =IFERROR(IF(VLOOKUP(C194,Entrada!A:C,3,FALSE)=Table1[[#Headers],[Entrada]],Table1[[#Headers],[Entrada]],""),"") | M194: =IFERROR(IF(VLOOKUP(C194,Virgen!A:C,3,FALSE)=Table1[[#Headers],[Virgen]],Table1[[#Headers],[Virgen]],""),"") | N194: =IFERROR(IF(VLOOKUP(C194,Paz!A:C,3,FALSE)=Table1[[#Headers],[Paz]],Table1[[#Headers],[Paz]],""),"") | O194: =IFERROR(IF(VLOOKUP(C194,Pan!A:C,3,FALSE)=Table1[[#Headers],[Pan]],Table1[[#Headers],[Pan]],""),"") | P194: =IFERROR(IF(VLOOKUP(C194,Comunión!A:C,3,FALSE)=Table1[[#Headers],[Comunión]],Table1[[#Headers],[Comunión]],""),"") | Q194: =IFERROR(IF(VLOOKUP(C194,Niños!A:C,3,FALSE)=Table1[[#Headers],[Niños]],Table1[[#Headers],[Niños]],""),"") | R194: =IFERROR(IF(VLOOKUP(C194,Laudes!A:C,3,FALSE)=Table1[[#Headers],[Laudes]],Table1[[#Headers],[Laudes]],""),"") | S194: =IFERROR(IF(VLOOKUP(C194,'Nuevo Testamento'!A:C,3,FALSE)=Table1[[#Headers],[Nuevo Testamento]],Table1[[#Headers],[Nuevo Testamento]],""),"") | T194: =IFERROR(IF(VLOOKUP(C194,'Antiguo Testamento'!A:C,3,FALSE)=Table1[[#Headers],[Antiguo Testamento]],Table1[[#Headers],[Antiguo Testamento]],""),"") | U194: =IFERROR(IF(VLOOKUP(C194,Final!A:C,3,FALSE)=Table1[[#Headers],[Final]],Table1[[#Headers],[Final]],""),"") | V194: {=_xlfn.LET( _xlpm.texto_limpio, _xlfn.REDUCE( LOWER(Table1[[#This Row],[Canto]]), {"á";"é";"í";"ó";"ú";"ñ";",";" "}, _xlfn.LAMBDA(_xlpm.acum,_xlpm.caracter, SUBSTITUTE(_xlpm.acum, _xlpm.caracter, CHOOSE(MATCH(_xlpm.caracter, {"á";"é";"í";"ó";"ú";"ñ";",";" "}, 0), "a","e","i","o","u","n","",""))) ), _xlfn.CONCAT("/cantos/src/chtml/", Table1[[#This Row],[iniciar]], "/", _xlpm.texto_limpio, ".html") )} -> /cantos/src/chtml/s/santoroma77.html | W194: =_xlfn.CONCAT("{id:",Table1[[#This Row],[Or'#]],",","title: ","""",Table1[[#This Row],[Canto]],"""",", subtitle: ","""",Table1[[#This Row],[subtitle]],"""",", ","category: ","""",Table1[[#This Row],[Categoria]],"""",", moments: [","""",Table1[[#This Row],[Adviento]],""",","""",Table1[[#This Row],[Navidad]],""",","""",Table1[[#This Row],[Cuaresma]],""",","""",Table1[[#This Row],[Pascua]],""",","""",Table1[[#This Row],[Pentecostés]],""",","""",Table1[[#This Row],[Entrada]],""",","""",Table1[[#This Row],[Virgen]],""",","""",Table1[[#This Row],[Paz]],""",","""",Table1[[#This Row],[Pan]],""",","""",Table1[[#This Row],[Comunión]],""",","""",Table1[[#This Row],[Niños]],""",","""",Table1[[#This Row],[Laudes]],""",","""",Table1[[#This Row],[Nuevo Testamento]],""",","""",Table1[[#This Row],[Antiguo Testamento]],""",","""",Table1[[#This Row],[Final]],"""","], url: ","""",Table1[[#This Row],[URL]],"""","},") -> {id:192,title: "Santo Roma 77", subtitle: "1988", category: "Liturgia", moments: ["","","","","","","","","","","","","","",""], url: "/cantos/src/chtml/s/santoroma77.html"},
A195: 145 | B195: 193 | C195: Se encontraron dos ángeles | D195: Melodía hebraica | E195: =LOWER(LEFT(Table1[[#This Row],[Canto]],1)) -> s | F195: Precatecumenado | G195: =IFERROR(IF(VLOOKUP(C195,Adviento!A:C,3,FALSE)=Table1[[#Headers],[Adviento]],Table1[[#Headers],[Adviento]],""),"") | H195: =IFERROR(IF(VLOOKUP(C195,Navidad!A:C,3,FALSE)=Table1[[#Headers],[Navidad]],Table1[[#Headers],[Navidad]],""),"") | I195: =IFERROR(IF(VLOOKUP(C195,Cuaresma!A:C,3,FALSE)=Table1[[#Headers],[Cuaresma]],Table1[[#Headers],[Cuaresma]],""),"") | J195: =IFERROR(IF(VLOOKUP(C195,Pascua!A:C,3,FALSE)=Table1[[#Headers],[Pascua]],Table1[[#Headers],[Pascua]],""),"") | K195: =IFERROR(IF(VLOOKUP(C195,Pentecostés!A:C,3,FALSE)=Table1[[#Headers],[Pentecostés]],Table1[[#Headers],[Pentecostés]],""),"") | L195: =IFERROR(IF(VLOOKUP(C195,Entrada!A:C,3,FALSE)=Table1[[#Headers],[Entrada]],Table1[[#Headers],[Entrada]],""),"") | M195: =IFERROR(IF(VLOOKUP(C195,Virgen!A:C,3,FALSE)=Table1[[#Headers],[Virgen]],Table1[[#Headers],[Virgen]],""),"") | N195: =IFERROR(IF(VLOOKUP(C195,Paz!A:C,3,FALSE)=Table1[[#Headers],[Paz]],Table1[[#Headers],[Paz]],""),"") -> Paz | O195: =IFERROR(IF(VLOOKUP(C195,Pan!A:C,3,FALSE)=Table1[[#Headers],[Pan]],Table1[[#Headers],[Pan]],""),"") | P195: =IFERROR(IF(VLOOKUP(C195,Comunión!A:C,3,FALSE)=Table1[[#Headers],[Comunión]],Table1[[#Headers],[Comunión]],""),"") | Q195: =IFERROR(IF(VLOOKUP(C195,Niños!A:C,3,FALSE)=Table1[[#Headers],[Niños]],Table1[[#Headers],[Niños]],""),"") -> Niños | R195: =IFERROR(IF(VLOOKUP(C195,Laudes!A:C,3,FALSE)=Table1[[#Headers],[Laudes]],Table1[[#Headers],[Laudes]],""),"") | S195: =IFERROR(IF(VLOOKUP(C195,'Nuevo Testamento'!A:C,3,FALSE)=Table1[[#Headers],[Nuevo Testamento]],Table1[[#Headers],[Nuevo Testamento]],""),"") | T195: =IFERROR(IF(VLOOKUP(C195,'Antiguo Testamento'!A:C,3,FALSE)=Table1[[#Headers],[Antiguo Testamento]],Table1[[#Headers],[Antiguo Testamento]],""),"") | U195: =IFERROR(IF(VLOOKUP(C195,Final!A:C,3,FALSE)=Table1[[#Headers],[Final]],Table1[[#Headers],[Final]],""),"") | V195: {=_xlfn.LET( _xlpm.texto_limpio, _xlfn.REDUCE( LOWER(Table1[[#This Row],[Canto]]), {"á";"é";"í";"ó";"ú";"ñ";",";" "}, _xlfn.LAMBDA(_xlpm.acum,_xlpm.caracter, SUBSTITUTE(_xlpm.acum, _xlpm.caracter, CHOOSE(MATCH(_xlpm.caracter, {"á";"é";"í";"ó";"ú";"ñ";",";" "}, 0), "a","e","i","o","u","n","",""))) ), _xlfn.CONCAT("/cantos/src/chtml/", Table1[[#This Row],[iniciar]], "/", _xlpm.texto_limpio, ".html") )} -> /cantos/src/chtml/s/seencontrarondosangeles.html | W195: =_xlfn.CONCAT("{id:",Table1[[#This Row],[Or'#]],",","title: ","""",Table1[[#This Row],[Canto]],"""",", subtitle: ","""",Table1[[#This Row],[subtitle]],"""",", ","category: ","""",Table1[[#This Row],[Categoria]],"""",", moments: [","""",Table1[[#This Row],[Adviento]],""",","""",Table1[[#This Row],[Navidad]],""",","""",Table1[[#This Row],[Cuaresma]],""",","""",Table1[[#This Row],[Pascua]],""",","""",Table1[[#This Row],[Pentecostés]],""",","""",Table1[[#This Row],[Entrada]],""",","""",Table1[[#This Row],[Virgen]],""",","""",Table1[[#This Row],[Paz]],""",","""",Table1[[#This Row],[Pan]],""",","""",Table1[[#This Row],[Comunión]],""",","""",Table1[[#This Row],[Niños]],""",","""",Table1[[#This Row],[Laudes]],""",","""",Table1[[#This Row],[Nuevo Testamento]],""",","""",Table1[[#This Row],[Antiguo Testamento]],""",","""",Table1[[#This Row],[Final]],"""","], url: ","""",Table1[[#This Row],[URL]],"""","},") -> {id:193,title: "Se encontraron dos ángeles", subtitle: "Melodía hebraica", category: "Precatecumenado", moments: ["","","","","","","","Paz","","","Niños","","","",""], url: "/cantos/src/chtml/s/seencontrarondosangeles.html"},
